2024-10-17 16:40:59,443 INFO    StreamThr :1972385 [internal.py:wandb_internal():86] W&B internal server running at pid: 1972385, started at: 2024-10-17 16:40:59.442221
2024-10-17 16:40:59,445 DEBUG   HandlerThread:1972385 [handler.py:handle_request():146] handle_request: status
2024-10-17 16:40:59,462 INFO    WriterThread:1972385 [datastore.py:open_for_write():87] open: /pbs/home/m/mferey/ML/caverns/outputs/2024-10-17/16-40-57/wandb/run-20241017_164059-9lgj9iqk/run-9lgj9iqk.wandb
2024-10-17 16:40:59,464 DEBUG   SenderThread:1972385 [sender.py:send():379] send: header
2024-10-17 16:40:59,481 DEBUG   SenderThread:1972385 [sender.py:send():379] send: run
2024-10-17 16:40:59,773 ERROR   SenderThread:1972385 [internal_api.py:execute():373] 403 response executing GraphQL.
2024-10-17 16:40:59,774 ERROR   SenderThread:1972385 [internal_api.py:execute():374] {"errors":[{"message":"permission denied","path":["upsertBucket"],"extensions":{"code":"PERMISSION_ERROR"}}],"data":{"upsertBucket":null}}
2024-10-17 16:40:59,774 ERROR   SenderThread:1972385 [sender.py:send_run():971] It appears that you do not have permission to access the requested resource. Please reach out to the project owner to grant you access. If you have the correct permissions, verify that there are no issues with your networking setup.(Error 403: Forbidden)
Traceback (most recent call last):
  File "/pbs/home/m/mferey/miniconda3/envs/watchmal/lib/python3.10/site-packages/wandb/sdk/lib/retry.py", line 131, in __call__
    result = self._call_fn(*args, **kwargs)
  File "/pbs/home/m/mferey/miniconda3/envs/watchmal/lib/python3.10/site-packages/wandb/sdk/internal/internal_api.py", line 369, in execute
    return self.client.execute(*args, **kwargs)  # type: ignore
  File "/pbs/home/m/mferey/miniconda3/envs/watchmal/lib/python3.10/site-packages/wandb/vendor/gql-0.2.0/wandb_gql/client.py", line 52, in execute
    result = self._get_result(document, *args, **kwargs)
  File "/pbs/home/m/mferey/miniconda3/envs/watchmal/lib/python3.10/site-packages/wandb/vendor/gql-0.2.0/wandb_gql/client.py", line 60, in _get_result
    return self.transport.execute(document, *args, **kwargs)
  File "/pbs/home/m/mferey/miniconda3/envs/watchmal/lib/python3.10/site-packages/wandb/sdk/lib/gql_request.py", line 59, in execute
    request.raise_for_status()
  File "/pbs/home/m/mferey/miniconda3/envs/watchmal/lib/python3.10/site-packages/requests/models.py", line 1024, in raise_for_status
    raise HTTPError(http_error_msg, response=self)
requests.exceptions.HTTPError: 403 Client Error: Forbidden for url: https://api.wandb.ai/graphql

During handling of the above exception, another exception occurred:

Traceback (most recent call last):
  File "/pbs/home/m/mferey/miniconda3/envs/watchmal/lib/python3.10/site-packages/wandb/sdk/internal/sender.py", line 969, in send_run
    server_run = self._init_run(run, config_value_dict)
  File "/pbs/home/m/mferey/miniconda3/envs/watchmal/lib/python3.10/site-packages/wandb/sdk/internal/sender.py", line 1014, in _init_run
    server_run, inserted, server_messages = self._api.upsert_run(
  File "/pbs/home/m/mferey/miniconda3/envs/watchmal/lib/python3.10/site-packages/wandb/apis/normalize.py", line 73, in wrapper
    raise err
  File "/pbs/home/m/mferey/miniconda3/envs/watchmal/lib/python3.10/site-packages/wandb/apis/normalize.py", line 41, in wrapper
    return func(*args, **kwargs)
  File "/pbs/home/m/mferey/miniconda3/envs/watchmal/lib/python3.10/site-packages/wandb/sdk/internal/internal_api.py", line 2217, in upsert_run
    response = self.gql(
  File "/pbs/home/m/mferey/miniconda3/envs/watchmal/lib/python3.10/site-packages/wandb/sdk/internal/internal_api.py", line 341, in gql
    ret = self._retry_gql(
  File "/pbs/home/m/mferey/miniconda3/envs/watchmal/lib/python3.10/site-packages/wandb/sdk/lib/retry.py", line 147, in __call__
    retry_timedelta_triggered = check_retry_fn(e)
  File "/pbs/home/m/mferey/miniconda3/envs/watchmal/lib/python3.10/site-packages/wandb/util.py", line 968, in check_retry_fn
    return fallback_retry_fn(e)
  File "/pbs/home/m/mferey/miniconda3/envs/watchmal/lib/python3.10/site-packages/wandb/util.py", line 910, in no_retry_auth
    raise CommError(
wandb.errors.CommError: It appears that you do not have permission to access the requested resource. Please reach out to the project owner to grant you access. If you have the correct permissions, verify that there are no issues with your networking setup.(Error 403: Forbidden)
2024-10-17 16:40:59,855 DEBUG   HandlerThread:1972385 [handler.py:handle_request():146] handle_request: shutdown
2024-10-17 16:40:59,856 INFO    HandlerThread:1972385 [handler.py:finish():866] shutting down handler
2024-10-17 16:41:00,481 INFO    WriterThread:1972385 [datastore.py:close():296] close: /pbs/home/m/mferey/ML/caverns/outputs/2024-10-17/16-40-57/wandb/run-20241017_164059-9lgj9iqk/run-9lgj9iqk.wandb
2024-10-17 16:41:00,783 INFO    SenderThread:1972385 [sender.py:finish():1546] shutting down sender
